<?xml version="1.0" encoding="UTF-8"?>
<testng-results skipped="0" failed="1" total="1" passed="0">
  <reporter-output>
  </reporter-output>
  <suite name="Default suite" duration-ms="54" started-at="2016-05-26T20:33:55Z" finished-at="2016-05-26T20:33:55Z">
    <groups>
    </groups>
    <test name="Default test" duration-ms="54" started-at="2016-05-26T20:33:55Z" finished-at="2016-05-26T20:33:55Z">
      <class name="test.YahooNewsTest">
        <test-method status="PASS" signature="beforeTest()[pri:0, instance:test.YahooNewsTest@16331538]" name="beforeTest" is-config="true" duration-ms="13" started-at="2016-05-26T13:33:55Z" finished-at="2016-05-26T13:33:55Z">
          <reporter-output>
          </reporter-output>
        </test-method> <!-- beforeTest -->
        <test-method status="FAIL" signature="yahooNews()[pri:0, instance:test.YahooNewsTest@16331538]" name="yahooNews" duration-ms="12" started-at="2016-05-26T13:33:55Z" finished-at="2016-05-26T13:33:55Z">
          <exception class="java.lang.AssertionError">
            <message>
              <![CDATA[Error Message expected [true] but found [false]]]>
            </message>
            <full-stacktrace>
              <![CDATA[java.lang.AssertionError: Error Message expected [true] but found [false]
	at org.testng.Assert.fail(Assert.java:94)
	at org.testng.Assert.failNotEquals(Assert.java:513)
	at org.testng.Assert.assertTrue(Assert.java:42)
	at test.YahooNewsTest.yahooNews(YahooNewsTest.java:21)
	at sun.reflect.NativeMethodAccessorImpl.invoke0(Native Method)
	at sun.reflect.NativeMethodAccessorImpl.invoke(Unknown Source)
	at sun.reflect.DelegatingMethodAccessorImpl.invoke(Unknown Source)
	at java.lang.reflect.Method.invoke(Unknown Source)
	at org.testng.internal.MethodInvocationHelper.invokeMethod(MethodInvocationHelper.java:86)
	at org.testng.internal.Invoker.invokeMethod(Invoker.java:646)
	at org.testng.internal.Invoker.invokeTestMethod(Invoker.java:823)
	at org.testng.internal.Invoker.invokeTestMethods(Invoker.java:1131)
	at org.testng.internal.TestMethodWorker.invokeTestMethods(TestMethodWorker.java:129)
	at org.testng.internal.TestMethodWorker.run(TestMethodWorker.java:112)
	at org.testng.TestRunner.privateRun(TestRunner.java:778)
	at org.testng.TestRunner.run(TestRunner.java:632)
	at org.testng.SuiteRunner.runTest(SuiteRunner.java:366)
	at org.testng.SuiteRunner.runSequentially(SuiteRunner.java:361)
	at org.testng.SuiteRunner.privateRun(SuiteRunner.java:319)
	at org.testng.SuiteRunner.run(SuiteRunner.java:268)
	at org.testng.SuiteRunnerWorker.runSuite(SuiteRunnerWorker.java:52)
	at org.testng.SuiteRunnerWorker.run(SuiteRunnerWorker.java:86)
	at org.testng.TestNG.runSuitesSequentially(TestNG.java:1225)
	at org.testng.TestNG.runSuitesLocally(TestNG.java:1150)
	at org.testng.TestNG.runSuites(TestNG.java:1075)
	at org.testng.TestNG.run(TestNG.java:1047)
	at org.testng.remote.AbstractRemoteTestNG.run(AbstractRemoteTestNG.java:126)
	at org.testng.remote.RemoteTestNG.initAndRun(RemoteTestNG.java:137)
	at org.testng.remote.RemoteTestNG.main(RemoteTestNG.java:58)
]]>
            </full-stacktrace>
          </exception> <!-- java.lang.AssertionError -->
          <reporter-output>
          </reporter-output>
        </test-method> <!-- yahooNews -->
        <test-method status="PASS" signature="afterTest()[pri:0, instance:test.YahooNewsTest@16331538]" name="afterTest" is-config="true" duration-ms="0" started-at="2016-05-26T13:33:55Z" finished-at="2016-05-26T13:33:55Z">
          <reporter-output>
          </reporter-output>
        </test-method> <!-- afterTest -->
      </class> <!-- test.YahooNewsTest -->
    </test> <!-- Default test -->
  </suite> <!-- Default suite -->
</testng-results>
